<?xml version="1.0" encoding="utf-8" ?>
<robot name="DM-Arm-Description">
    <link name="base_footprint" />
    <joint name="base_footprint_joint" type="fixed">
        <parent link="base_footprint" />
        <child link="base_link" />
        <origin xyz="0 0 0" rpy="0 0 0" />
    </joint>
    <link name="base_link">
        <visual>
            <origin xyz="0 0 0" rpy="0 0 0" />
            <geometry>
                <mesh filename="package://dm_arm_description/meshes/visual/base_link.dae" />
            </geometry>
            <material name="">
                <color rgba="0.95 0.95 0.95 1" />
            </material>
        </visual>
        <collision>
            <origin xyz="0 0 0" rpy="0 0 0" />
            <geometry>
                <mesh filename="package://dm_arm_description/meshes/collision/base_link.stl" />
            </geometry>
        </collision>
        <inertial>
            <mass value="0.1" />
            <origin xyz="0 0 0" rpy="0 0 0" />
            <inertia ixx="0.03" iyy="0.03" izz="0.03" ixy="0.0" ixz="0.0" iyz="0.0" />
        </inertial>
    </link>
    <link name="link1-2">
        <visual>
            <origin xyz="0 0 0" rpy="0 0 0" />
            <geometry>
                <mesh filename="package://dm_arm_description/meshes/visual/link1-2.dae" />
            </geometry>
            <material name="">
                <color rgba="0.95 0.95 0.95 1" />
            </material>
        </visual>
        <collision>
            <origin xyz="0 0 0" rpy="0 0 0" />
            <geometry>
                <mesh filename="package://dm_arm_description/meshes/collision/link1-2.stl" />
            </geometry>
        </collision>
        <inertial>
            <mass value="0.1" />
            <origin xyz="0 0 0" rpy="0 0 0" />
            <inertia ixx="0.03" iyy="0.03" izz="0.03" ixy="0.0" ixz="0.0" iyz="0.0" />
        </inertial>
    </link>
    <joint name="joint1" type="revolute">
        <origin xyz="0 0 0.0615" rpy="0 0 0" />
        <parent link="base_link" />
        <child link="link1-2" />
        <axis xyz="0 0 1" />
        <limit lower="-2.0943951023931953" upper="2.0943951023931953" effort="100" velocity="3" />
    </joint>
    <link name="link1">
        <visual>
            <origin xyz="0 0 0" rpy="0 0 0" />
            <geometry>
                <mesh filename="package://dm_arm_description/meshes/visual/link1.dae" />
            </geometry>
            <material name="">
                <color rgba="0.75 0.75 0.75 1" />
            </material>
        </visual>
        <collision>
            <origin xyz="0 0 0" rpy="0 0 0" />
            n
            <geometry>
                <mesh filename="package://dm_arm_description/meshes/collision/link1.stl" />
            </geometry>
        </collision>
        <inertial>
            <mass value="0.1" />
            <origin xyz="0 0 0" rpy="0 0 0" />
            <inertia ixx="0.03" iyy="0.03" izz="0.03" ixy="0.0" ixz="0.0" iyz="0.0" />
        </inertial>
    </link>
    <joint name="joint2" type="revolute">
        <origin xyz="0 0.02 0.0385" rpy="0 0 0" />
        <parent link="link1-2" />
        <child link="link1" />
        <axis xyz="-1 0 0" />
        <limit lower="-0.0349065850398" upper="3.141592653589793" effort="100" velocity="3" />
    </joint>
    <link name="link2">
        <visual>
            <origin xyz="0 0 0" rpy="0 0 0" />
            <geometry>
                <mesh filename="package://dm_arm_description/meshes/visual/link2.dae" />
            </geometry>
            <material name="">
                <color rgba="0.75 0.75 0.75 1" />
            </material>
        </visual>
        <collision>
            <origin xyz="0 0 0" rpy="0 0 0" />
            <geometry>
                <mesh filename="package://dm_arm_description/meshes/collision/link2.stl" />
            </geometry>
        </collision>
        <inertial>
            <mass value="0.1" />
            <origin xyz="0 0 0" rpy="0 0 0" />
            <inertia ixx="0.03" iyy="0.03" izz="0.03" ixy="0.0" ixz="0.0" iyz="0.0" />
        </inertial>
    </link>
    <joint name="joint3" type="revolute">
        <origin xyz="0 -0.264 0" rpy="0 0 0" />
        <parent link="link1" />
        <child link="link2" />
        <axis xyz="1 0 0" />
        <limit lower="-0.0698131700797" upper="4.71238898038469" effort="100" velocity="3" />
    </joint>
    <link name="link4-5">
        <visual>
            <origin xyz="0 0 0" rpy="0 0 0" />
            <geometry>
                <mesh filename="package://dm_arm_description/meshes/visual/link4-5.dae" />
            </geometry>
            <material name="">
                <color rgba="0.95 0.95 0.95 1" />
            </material>
        </visual>
        <collision>
            <origin xyz="0 0 0" rpy="0 0 0" />
            <geometry>
                <mesh filename="package://dm_arm_description/meshes/collision/link4-5.stl" />
            </geometry>
        </collision>
        <inertial>
            <mass value="0.1" />
            <origin xyz="0 0 0" rpy="0 0 0" />
            <inertia ixx="0.03" iyy="0.03" izz="0.03" ixy="0.0" ixz="0.0" iyz="0.0" />
        </inertial>
    </link>
    <joint name="joint4" type="revolute">
        <origin xyz="0 0.244004 0.059971" rpy="0 0 0" />
        <parent link="link2" />
        <child link="link4-5" />
        <axis xyz="1 0 0" />
        <limit lower="-1.5707963267948966" upper="1.5707963267948966" effort="20" velocity="3" />
    </joint>
    <link name="link5-6">
        <visual>
            <origin xyz="0 0 0" rpy="0 0 0" />
            <geometry>
                <mesh filename="package://dm_arm_description/meshes/visual/link5-6.dae" />
            </geometry>
            <material name="">
                <color rgba="0.95 0.95 0.95 1" />
            </material>
        </visual>
        <collision>
            <origin xyz="0 0 0" rpy="0 0 0" />
            <geometry>
                <mesh filename="package://dm_arm_description/meshes/collision/link5-6.stl" />
            </geometry>
        </collision>
        <inertial>
            <mass value="0.1" />
            <origin xyz="0 0 0" rpy="0 0 0" />
            <inertia ixx="0.03" iyy="0.03" izz="0.03" ixy="0.0" ixz="0.0" iyz="0.0" />
        </inertial>
    </link>
    <joint name="joint5" type="revolute">
        <origin xyz="0 0.061868 0.0425" rpy="0 0 0" />
        <parent link="link4-5" />
        <child link="link5-6" />
        <axis xyz="0 0 -1" />
        <limit lower="-1.5707963267948966" upper="1.5707963267948966" effort="20" velocity="3" />
    </joint>
    <link name="link6-7">
        <visual>
            <origin xyz="0 0 0" rpy="0 0 0" />
            <geometry>
                <mesh filename="package://dm_arm_description/meshes/visual/link6-7.dae" />
            </geometry>
            <material name="">
                <color rgba="0.25 0.25 0.25 1" />
            </material>
        </visual>
        <collision>
            <origin xyz="0 0 0" rpy="0 0 0" />
            <geometry>
                <mesh filename="package://dm_arm_description/meshes/collision/link6-7.stl" />
            </geometry>
        </collision>
        <inertial>
            <mass value="0.1" />
            <origin xyz="0 0 0" rpy="0 0 0" />
            <inertia ixx="0.03" iyy="0.03" izz="0.03" ixy="0.0" ixz="0.0" iyz="0.0" />
        </inertial>
    </link>
    <joint name="joint6" type="revolute">
        <origin xyz="0.0 0.032 -0.0425" rpy="0 0 0" />
        <parent link="link5-6" />
        <child link="link6-7" />
        <axis xyz="0 1 0" />
        <limit lower="-3.141592653589793" upper="3.141592653589793" effort="20" velocity="3" />
    </joint>
    <joint name="joint_tcp" type="fixed">
        <parent link="link6-7" />
        <child link="link_tcp" />
        <origin xyz="0.0 0.0 0.0" rpy="-1.5708 0 0" />
    </joint>
    <link name="link_tcp" />
    <link name="finger_left">
        <visual>
            <origin xyz="0 0 0" rpy="0 0 0" />
            <geometry>
                <mesh filename="package://dm_arm_description/meshes/visual/finger_left.dae" />
            </geometry>
            <material name="">
                <color rgba="0.25 0.25 0.25 1" />
            </material>
        </visual>
        <collision>
            <origin xyz="0 0 0" rpy="0 0 0" />
            <geometry>
                <mesh filename="package://dm_arm_description/meshes/collision/finger_left.stl" />
            </geometry>
        </collision>
        <inertial>
            <mass value="0.1" />
            <origin xyz="0 0 0" rpy="0 0 0" />
            <inertia ixx="0.03" iyy="0.03" izz="0.03" ixy="0.0" ixz="0.0" iyz="0.0" />
        </inertial>
    </link>
    <joint name="gripper_left" type="prismatic">
        <origin xyz="0 0 0" rpy="0 0 0" />
        <parent link="link6-7" />
        <child link="finger_left" />
        <axis xyz="-1 0 0" />
        <limit lower="-0.045" upper="0.0" effort="20" velocity="0.2" />
    </joint>
    <link name="finger_right">
        <visual>
            <origin xyz="0 0 0" rpy="0 0 0" />
            <geometry>
                <mesh filename="package://dm_arm_description/meshes/visual/finger_right.dae" />
            </geometry>
            <material name="">
                <color rgba="0.25 0.25 0.25 1" />
            </material>
        </visual>
        <collision>
            <origin xyz="0 0 0" rpy="0 0 0" />
            <geometry>
                <mesh filename="package://dm_arm_description/meshes/collision/finger_right.stl" />
            </geometry>
        </collision>
        <inertial>
            <mass value="0.1" />
            <origin xyz="0 0 0" rpy="0 0 0" />
            <inertia ixx="0.03" iyy="0.03" izz="0.03" ixy="0.0" ixz="0.0" iyz="0.0" />
        </inertial>
    </link>
    <joint name="gripper_right" type="prismatic">
        <origin xyz="0 0 0" rpy="0 0 0" />
        <parent link="link6-7" />
        <child link="finger_right" />
        <axis xyz="1 0 0" />
        <limit lower="-0.045" upper="0.0" effort="20" velocity="0.2" />
        <mimic joint="gripper_left" multiplier="1" offset="0" />
    </joint>
    <link name="tool0" />
    <joint name="gripper_tool0" type="fixed">
        <origin xyz="0 0.158 0" rpy="-1.5707963267948966 0 0" />
        <parent link="link6-7" />
        <child link="tool0" />
    </joint>
    <transmission name="trans_joint1">
        <type>transmission_interface/SimpleTransmission</type>
        <joint name="joint1">
            <hardwareInterface>hardware_interface/PositionJointInterface</hardwareInterface>
        </joint>
        <actuator name="joint1_motor">
            <hardwareInterface>hardware_interface/PositionJointInterface</hardwareInterface>
            <mechanicalReduction>1</mechanicalReduction>
        </actuator>
    </transmission>
    <transmission name="trans_joint2">
        <type>transmission_interface/SimpleTransmission</type>
        <joint name="joint2">
            <hardwareInterface>hardware_interface/PositionJointInterface</hardwareInterface>
        </joint>
        <actuator name="joint2_motor">
            <hardwareInterface>hardware_interface/PositionJointInterface</hardwareInterface>
            <mechanicalReduction>1</mechanicalReduction>
        </actuator>
    </transmission>
    <transmission name="trans_joint3">
        <type>transmission_interface/SimpleTransmission</type>
        <joint name="joint3">
            <hardwareInterface>hardware_interface/PositionJointInterface</hardwareInterface>
        </joint>
        <actuator name="joint3_motor">
            <hardwareInterface>hardware_interface/PositionJointInterface</hardwareInterface>
            <mechanicalReduction>1</mechanicalReduction>
        </actuator>
    </transmission>
    <transmission name="trans_joint4">
        <type>transmission_interface/SimpleTransmission</type>
        <joint name="joint4">
            <hardwareInterface>hardware_interface/PositionJointInterface</hardwareInterface>
        </joint>
        <actuator name="joint4_motor">
            <hardwareInterface>hardware_interface/PositionJointInterface</hardwareInterface>
            <mechanicalReduction>1</mechanicalReduction>
        </actuator>
    </transmission>
    <transmission name="trans_joint5">
        <type>transmission_interface/SimpleTransmission</type>
        <joint name="joint5">
            <hardwareInterface>hardware_interface/PositionJointInterface</hardwareInterface>
        </joint>
        <actuator name="joint5_motor">
            <hardwareInterface>hardware_interface/PositionJointInterface</hardwareInterface>
            <mechanicalReduction>1</mechanicalReduction>
        </actuator>
    </transmission>
    <transmission name="trans_joint6">
        <type>transmission_interface/SimpleTransmission</type>
        <joint name="joint6">
            <hardwareInterface>hardware_interface/PositionJointInterface</hardwareInterface>
        </joint>
        <actuator name="joint6_motor">
            <hardwareInterface>hardware_interface/PositionJointInterface</hardwareInterface>
            <mechanicalReduction>1</mechanicalReduction>
        </actuator>
    </transmission>
    <transmission name="trans_gripper_left">
        <type>transmission_interface/SimpleTransmission</type>
        <joint name="gripper_left">
            <hardwareInterface>hardware_interface/PositionJointInterface</hardwareInterface>
        </joint>
        <actuator name="gripper_left_motor">
            <hardwareInterface>hardware_interface/PositionJointInterface</hardwareInterface>
            <mechanicalReduction>1</mechanicalReduction>
        </actuator>
    </transmission>
    <transmission name="trans_gripper_right">
        <type>transmission_interface/SimpleTransmission</type>
        <joint name="gripper_right">
            <hardwareInterface>hardware_interface/EffortJointInterface</hardwareInterface>
        </joint>
        <actuator name="gripper_right_motor">
            <hardwareInterface>hardware_interface/EffortJointInterface</hardwareInterface>
            <mechanicalReduction>1</mechanicalReduction>
        </actuator>
    </transmission>
    <gazebo>
        <plugin name="gazebo_ros_control">
            <robotNamespace>/</robotNamespace>
        </plugin>
    </gazebo>
</robot>

